<?xml version="1.0" ?>
<!-- =================================================================================== -->
<!-- |    This document was autogenerated by xacro from src/urdf_learning/urdf/main.xacro | -->
<!-- |    EDITING THIS FILE BY HAND IS NOT RECOMMENDED                                 | -->
<!-- =================================================================================== -->
<robot name="urdf_learning">
  <!-- <robot name="urdf_learning"> -->
  <!-- 标签定义 -->
  <!-- <material name="blue">
        <color rgba="0.5 0.5 1 0.8"/>
    </material>
    <material name="black">
        <color rgba="0.1 0.1 0.1 1"/>
    </material>
    <material name="gray">
        <color rgba="0.1 0.1 0.1 1"/>
    </material>
    <material name="white">
        <color rgba="0.1 0.1 0.1 1"/>
    </material> -->
  <!-- <xacro:property name="base_to_rf_motor_joint_xyz" value="0.03 ${-base_to_motor_joint_y} -0.02"/> -->
  <!-- <xacro:property name="base_to_rf_motor_joint_rpy" value="0 0 0"/> -->
  <!-- <xacro:property name="rf_motor_to_wheel_joint_xyz" value="0 ${-motor_to_wheel_joint_y} 0"/> -->
  <!-- <xacro:property name="rf_motor_to_wheel_joint_rpy" value="0 0 0"/> -->
  <link name="base_link">
    <visual>
      <origin rpy="0 0 0" xyz="0 0 0"/>
      <geometry>
        <cylinder length="0.08" radius="0.17"/>
      </geometry>
      <material name="blue">
        <color rgba="0.9 0.9 0.1 0.5"/>
      </material>
    </visual>
    <collision>
      <origin rpy="0 0 0" xyz="0 0 0"/>
      <geometry>
        <cylinder length="0.08" radius="0.17"/>
      </geometry>
    </collision>
    <inertial>
      <mass value="1"/>
      <inertia ixx="0.007758333333333335" ixy="0" ixz="0" iyy="0.007758333333333335" iyz="0" izz="0.014450000000000003"/>
    </inertial>
  </link>
  <gazebo reference="base_link">
    <material>Gazebo/Blue</material>
  </gazebo>
  <link name="caster_link">
    <visual>
      <origin rpy="0 0 0" xyz="0 0 0"/>
      <geometry>
        <sphere radius="0.01"/>
      </geometry>
      <material name="black">
        <color rgba="0.1 0.1 0.1 1"/>
      </material>
    </visual>
    <collision>
      <origin rpy="0 0 0" xyz="0 0 0"/>
      <geometry>
        <sphere radius="0.01"/>
      </geometry>
    </collision>
    <inertial>
      <mass value="0.05"/>
      <inertia ixx="2.0000000000000003e-06" ixy="0" ixz="0" iyy="2.0000000000000003e-06" iyz="0" izz="2.0000000000000003e-06"/>
    </inertial>
  </link>
  <gazebo reference="caster_link">
    <material>Gazebo/Black</material>
  </gazebo>
  <link name="lf_motor_link">
    <visual>
      <origin rpy="1.5707963267945 0 0" xyz="0 0.001 0"/>
      <geometry>
        <cylinder length="0.1" radius="0.005"/>
      </geometry>
      <material name="red">
        <color rgba="0.5 0.5 0.5 1"/>
      </material>
    </visual>
    <collision>
      <origin rpy="1.5707963267945 0 0" xyz="0 0.001 0"/>
      <geometry>
        <cylinder length="0.1" radius="0.005"/>
      </geometry>
    </collision>
    <inertial>
      <mass value="0.1"/>
      <inertia ixx="8.395833333333336e-05" ixy="0" ixz="0" iyy="8.395833333333336e-05" iyz="0" izz="1.25e-06"/>
    </inertial>
  </link>
  <gazebo reference="lf_motor_link">
    <material>Gazebo/Red</material>
  </gazebo>
  <link name="rf_motor_link">
    <visual>
      <origin rpy="1.5707963267945 0 0" xyz="0 -0.001 0"/>
      <geometry>
        <cylinder length="0.1" radius="0.005"/>
      </geometry>
      <material name="red">
        <color rgba="0.5 0.5 0.5 1"/>
      </material>
    </visual>
    <collision>
      <origin rpy="1.5707963267945 0 0" xyz="0 -0.001 0"/>
      <geometry>
        <cylinder length="0.1" radius="0.005"/>
      </geometry>
    </collision>
    <inertial>
      <mass value="0.1"/>
      <inertia ixx="8.395833333333336e-05" ixy="0" ixz="0" iyy="8.395833333333336e-05" iyz="0" izz="1.25e-06"/>
    </inertial>
  </link>
  <gazebo reference="rf_motor_link">
    <material>Gazebo/Red</material>
  </gazebo>
  <link name="lf_wheel_link">
    <visual>
      <origin rpy="1.5707963267945 0 0" xyz="0 0.025 0"/>
      <geometry>
        <cylinder length="0.015" radius="0.03"/>
      </geometry>
      <material name="green">
        <color rgba="0.9 0.9 0.9 1"/>
      </material>
    </visual>
    <collision>
      <origin rpy="1.5707963267945 0 0" xyz="0 0.025 0"/>
      <geometry>
        <cylinder length="0.015" radius="0.03"/>
      </geometry>
    </collision>
    <inertial>
      <mass value="0.05"/>
      <inertia ixx="1.2187499999999998e-05" ixy="0" ixz="0" iyy="1.2187499999999998e-05" iyz="0" izz="2.2499999999999998e-05"/>
    </inertial>
  </link>
  <gazebo reference="lf_wheel_link">
    <material>Gazebo/Green</material>
  </gazebo>
  <link name="rf_wheel_link">
    <visual>
      <origin rpy="1.5707963267945 0 0" xyz="0 -0.025 0"/>
      <geometry>
        <cylinder length="0.015" radius="0.03"/>
      </geometry>
      <material name="green">
        <color rgba="0.9 0.9 0.9 1"/>
      </material>
    </visual>
    <collision>
      <origin rpy="1.5707963267945 0 0" xyz="0 -0.025 0"/>
      <geometry>
        <cylinder length="0.015" radius="0.03"/>
      </geometry>
    </collision>
    <inertial>
      <mass value="0.05"/>
      <inertia ixx="1.2187499999999998e-05" ixy="0" ixz="0" iyy="1.2187499999999998e-05" iyz="0" izz="2.2499999999999998e-05"/>
    </inertial>
  </link>
  <gazebo reference="rf_wheel_link">
    <material>Gazebo/Green</material>
  </gazebo>
  <joint name="base_to_caster_joint" type="continuous">
    <parent link="base_link"/>
    <child link="caster_link"/>
    <origin rpy="0 0 0" xyz="0.1 0 -0.04"/>
  </joint>
  <joint name="base_to_lf_motor_joint" type="fixed">
    <parent link="base_link"/>
    <child link="lf_motor_link"/>
    <origin rpy="0 0 0" xyz="-0.03 0.1 -0.02"/>
    <axis xyz="0 1 0"/>
  </joint>
  <joint name="base_to_rf_motor_joint" type="fixed">
    <parent link="base_link"/>
    <child link="rf_motor_link"/>
    <origin rpy="0 0 0" xyz="-0.03 -0.1 -0.02"/>
    <axis xyz="0 1 0"/>
  </joint>
  <joint name="motor_to_lf_wheel_joint" type="continuous">
    <parent link="lf_motor_link"/>
    <child link="lf_wheel_link"/>
    <origin rpy="0 0 0" xyz="0 0.025 0"/>
    <axis xyz="0 1 0"/>
  </joint>
  <joint name="motor_to_rf_wheel_joint" type="continuous">
    <parent link="rf_motor_link"/>
    <child link="rf_wheel_link"/>
    <origin rpy="0 0 0" xyz="0 -0.025 0"/>
    <axis xyz="0 1 0"/>
  </joint>
</robot>

